Бот запущен.
list index out of range
Traceback (most recent call last):
  File "C:\Dev\api_sp1_bot\homework.py", line 56, in main
    last_homework = homeworks['homeworks'][0]
IndexError: list index out of range
Сообщение отправлено
list index out of range
Traceback (most recent call last):
  File "C:\Dev\api_sp1_bot\homework.py", line 56, in main
    last_homework = homeworks['homeworks'][0]
IndexError: list index out of range
Сообщение отправлено
list index out of range
Traceback (most recent call last):
  File "C:\Dev\api_sp1_bot\homework.py", line 56, in main
    last_homework = homeworks['homeworks'][0]
IndexError: list index out of range
Сообщение отправлено
list index out of range
Traceback (most recent call last):
  File "C:\Dev\api_sp1_bot\homework.py", line 56, in main
    last_homework = homeworks['homeworks'][0]
IndexError: list index out of range
Сообщение отправлено
Бот запущен.
